<?xml version="1.0" encoding="UTF-8"?>
<robot generator="Robot 3.2.2 (Python 3.8.3 on win32)" generated="20240523 11:09:18.375" rpa="false">
<suite id="s1" name="Suites">
<suite id="s1-s1" name="CreateIC" source="C:\Users\AGebril\PycharmProjects\QC_Automation_Claim\Tests\CreateIC.robot">
<test id="s1-s1-t1" name="${Testcase id} ${Type} ${Desc}">
<status status="FAIL" starttime="20240523 11:09:18.819" endtime="20240523 11:09:18.821" critical="yes">Test case contains no keywords.</status>
</test>
<doc>Suite description</doc>
<status status="FAIL" starttime="20240523 11:09:18.401" endtime="20240523 11:09:18.822"></status>
</suite>
<status status="FAIL" starttime="20240523 11:09:18.385" endtime="20240523 11:09:18.824"></status>
</suite>
<statistics>
<total>
<stat pass="0" fail="1">Critical Tests</stat>
<stat pass="0" fail="1">All Tests</stat>
</total>
<tag>
</tag>
<suite>
<stat pass="0" fail="1" id="s1" name="Suites">Suites</stat>
<stat pass="0" fail="1" id="s1-s1" name="CreateIC">Suites.CreateIC</stat>
</suite>
</statistics>
<errors>
<msg timestamp="20240523 11:09:18.800" level="ERROR">Error in file 'C:\Users\AGebril\PycharmProjects\QC_Automation_Claim\Tests\CreateIC.robot' on line 10: Resource file '..\Resources\Keyword\CliamSub.robot' does not exist.</msg>
<msg timestamp="20240523 11:09:18.815" level="ERROR">[ DataDriver ] Error in robot file:
  File "C:\Users\AGebril\PycharmProjects\QC_Automation_Claim\Tests\CreateIC.robot", line 0</msg>
<msg timestamp="20240523 11:09:18.815" level="ERROR">In source file:
  File "../Resources/DataDriven/CreateIC.xlsx", line 0</msg>
<msg timestamp="20240523 11:09:18.817" level="ERROR">Calling method '_start_suite' of listener 'DataDriver' failed: FileNotFoundError: File attribute was not a full path. Tried to find C:\Users\AGebril\PycharmProjects\QC_Automation_Claim\Tests\../Resources/DataDriven/CreateIC.xlsx but file does not exist.</msg>
</errors>
</robot>
